Workbook

Sheet README
A1: Credit Migration Scenario Calculator
A3: What this is
A4: Pure-formula Excel port of the cascade-logit Markov engine from src/markov_dgp.py and src/markov_engine.py -- no macros, no add-ins, opens anywhere. Generated by src/excel_export.py from model_weights.json -- do not edit the Calc or Model_Weights tabs by hand, they will be overwritten on the next regeneration.
A6: How to use it
A7: 1. Go to the 'Scenario' tab.
A8: 2. Edit the two yellow input cells: Delta Earnings Growth and Delta 10Y Yield, both in PERCENTAGE POINTS (type 0.5 for +0.5%, i.e. +50bp -- not 0.005). This matches exactly how the Python model was fit.
A9: 3. Edit Cumulative Horizon (quarters, 1-60) to choose how many quarters to compound the scenario over. If this is ever invalid (0, negative, non-integer), the Cumulative grid shows 'Invalid horizon' instead of an error.
A10: 4. The 'Scenario check' cell tells you if your inputs are within the range the model was actually fit on. If they're beyond the per-feature cap (see the Model_Weights tab), it also shows an INPUT CAPPED note -- inputs that extreme are clamped before the matrix math runs, so the sigmoid can't saturate into a literal, historically-unprecedented 0%/100% (e.g. "100% of IG demotes in one quarter"). The displayed matrix reflects the CAPPED value whenever that note appears, not your literal typed input.
A11: 5. The two 4x4 grids below show the next-quarter and N-quarter-cumulative transition matrices as real percentages, colour-scaled green (low probability) to red (high probability).
A12: 6. If a grid ever looks stuck (doesn't change when you edit the inputs), press Ctrl+Alt+F9 to force a full recalculation.
A14: IMPORTANT: where the output becomes static (flat)
A15: Delta Earnings Growth is clamped to [-2.343, 1.943]. Any input at or beyond that boundary computes the SAME result as the boundary value itself -- this is not a bug.
... A25: All beta_hat values here come directly from model_weights.json, generated by python run_pipeline.py. Re-run that (which now also regenerates this file) to refresh the numbers.

Sheet Scenario
A1: Credit Migration Scenario Calculator
A3: Inputs (percentage points, e.g. 0.5 = +0.5%)
A4: Delta Earnings Growth | C4: 1
A5: Delta 10Y Yield | C5: 10
A6: Cumulative Horizon (quarters, 1-60) | C6: 10
A7: Scenario check | C7: =IF(OR(Calc!C3<Model_Weights!B20, Calc!C3>Model_Weights!C20, Calc!D3<Model_Weights!B21, Calc!D3>Model_Weights!C21, Calc!E3<Model_Weights!B22, Calc!E3>Model_Weights!C22), "EXTRAPOLATION WARNING: input(s) outside observed training range" & IF(OR(Calc!C4<>"",Calc!D4<>"",Calc!E4<>""), " | INPUT CAPPED (result reflects capped value): " & TRIM(Calc!C4&" "&Calc!D4&" "&Calc!E4), ""), "OK - within training range") -> EXTRAPOLATION WARNING: input(s) outside observed training range | INPUT CAPPED (result reflects capped value): Interaction: 10.000 -> 0.674
A9: Next-Quarter Transition Matrix
B10: -> IG | C10: -> NonIG | D10: -> Junk | E10: -> Default
A11: IG -> | B11: =TEXT(INDEX(Calc!$B$39:$E$42, 1, 1),"0.00%") -> 47.40% | C11: =TEXT(INDEX(Calc!$B$39:$E$42, 1, 2),"0.00%") -> 0.13% | D11: =TEXT(INDEX(Calc!$B$39:$E$42, 1, 3),"0.00%") -> 52.47% | E11: =TEXT(INDEX(Calc!$B$39:$E$42, 1, 4),"0.00%") -> 0.00%
A12: NonIG -> | B12: =TEXT(INDEX(Calc!$B$39:$E$42, 2, 1),"0.00%") -> 4.00% | C12: =TEXT(INDEX(Calc!$B$39:$E$42, 2, 2),"0.00%") -> 2.95% | D12: =TEXT(INDEX(Calc!$B$39:$E$42, 2, 3),"0.00%") -> 8.18% | E12: =TEXT(INDEX(Calc!$B$39:$E$42, 2, 4),"0.00%") -> 84.88%
A13: Junk -> | B13: =TEXT(INDEX(Calc!$B$39:$E$42, 3, 1),"0.00%") -> 0.00% | C13: =TEXT(INDEX(Calc!$B$39:$E$42, 3, 2),"0.00%") -> 5.00% | D13: =TEXT(INDEX(Calc!$B$39:$E$42, 3, 3),"0.00%") -> 0.00% | E13: =TEXT(INDEX(Calc!$B$39:$E$42, 3, 4),"0.00%") -> 95.00%
A14: Default -> | B14: =TEXT(INDEX(Calc!$B$39:$E$42, 4, 1),"0.00%") -> 0.00% | C14: =TEXT(INDEX(Calc!$B$39:$E$42, 4, 2),"0.00%") -> 0.00% | D14: =TEXT(INDEX(Calc!$B$39:$E$42, 4, 3),"0.00%") -> 0.00% | E14: =TEXT(INDEX(Calc!$B$39:$E$42, 4, 4),"0.00%") -> 100.00%
A16: N-Quarter Cumulative Transition Matrix (sustained scenario)
B17: -> IG | C17: -> NonIG | D17: -> Junk | E17: -> Default
A18: IG -> | B18: =IF(OR($C$6<1,$C$6<>ROUND($C$6,0),$C$6>60),"Invalid horizon",TEXT(INDEX(Calc!$B$44:$E$283, ($C$6-1)*4+1, 1),"0.00%")) -> 0.06% | C18: =IF(OR($C$6<1,$C$6<>ROUND($C$6,0),$C$6>60),"Invalid horizon",TEXT(INDEX(Calc!$B$44:$E$283, ($C$6-1)*4+1, 2),"0.00%")) -> 0.01% | D18: =IF(OR($C$6<1,$C$6<>ROUND($C$6,0),$C$6>60),"Invalid horizon",TEXT(INDEX(Calc!$B$44:$E$283, ($C$6-1)*4+1, 3),"0.00%")) -> 0.07% | E18: =IF(OR($C$6<1,$C$6<>ROUND($C$6,0),$C$6>60),"Invalid horizon",TEXT(INDEX(Calc!$B$44:$E$283, ($C$6-1)*4+1, 4),"0.00%")) -> 99.86%
A19: NonIG -> | B19: =IF(OR($C$6<1,$C$6<>ROUND($C$6,0),$C$6>60),"Invalid horizon",TEXT(INDEX(Calc!$B$44:$E$283, ($C$6-1)*4+2, 1),"0.00%")) -> 0.01% | C19: =IF(OR($C$6<1,$C$6<>ROUND($C$6,0),$C$6>60),"Invalid horizon",TEXT(INDEX(Calc!$B$44:$E$283, ($C$6-1)*4+2, 2),"0.00%")) -> 0.00% | D19: =IF(OR($C$6<1,$C$6<>ROUND($C$6,0),$C$6>60),"Invalid horizon",TEXT(INDEX(Calc!$B$44:$E$283, ($C$6-1)*4+2, 3),"0.00%")) -> 0.01% | E19: =IF(OR($C$6<1,$C$6<>ROUND($C$6,0),$C$6>60),"Invalid horizon",TEXT(INDEX(Calc!$B$44:$E$283, ($C$6-1)*4+2, 4),"0.00%")) -> 99.99%
A20: Junk -> | B20: =IF(OR($C$6<1,$C$6<>ROUND($C$6,0),$C$6>60),"Invalid horizon",TEXT(INDEX(Calc!$B$44:$E$283, ($C$6-1)*4+3, 1),"0.00%")) -> 0.00% | C20: =IF(OR($C$6<1,$C$6<>ROUND($C$6,0),$C$6>60),"Invalid horizon",TEXT(INDEX(Calc!$B$44:$E$283, ($C$6-1)*4+3, 2),"0.00%")) -> 0.00% | D20: =IF(OR($C$6<1,$C$6<>ROUND($C$6,0),$C$6>60),"Invalid horizon",TEXT(INDEX(Calc!$B$44:$E$283, ($C$6-1)*4+3, 3),"0.00%")) -> 0.00% | E20: =IF(OR($C$6<1,$C$6<>ROUND($C$6,0),$C$6>60),"Invalid horizon",TEXT(INDEX(Calc!$B$44:$E$283, ($C$6-1)*4+3, 4),"0.00%")) -> 100.00%
A21: Default -> | B21: =IF(OR($C$6<1,$C$6<>ROUND($C$6,0),$C$6>60),"Invalid horizon",TEXT(INDEX(Calc!$B$44:$E$283, ($C$6-1)*4+4, 1),"0.00%")) -> 0.00% | C21: =IF(OR($C$6<1,$C$6<>ROUND($C$6,0),$C$6>60),"Invalid horizon",TEXT(INDEX(Calc!$B$44:$E$283, ($C$6-1)*4+4, 2),"0.00%")) -> 0.00% | D21: =IF(OR($C$6<1,$C$6<>ROUND($C$6,0),$C$6>60),"Invalid horizon",TEXT(INDEX(Calc!$B$44:$E$283, ($C$6-1)*4+4, 3),"0.00%")) -> 0.00% | E21: =IF(OR($C$6<1,$C$6<>ROUND($C$6,0),$C$6>60),"Invalid horizon",TEXT(INDEX(Calc!$B$44:$E$283, ($C$6-1)*4+4, 4),"0.00%")) -> 100.00%
A23: Note: output becomes static (flat) beyond these input bounds:
A24: See the Model_Weights tab (EXTRAPOLATION CAP BOUNDS) for the exact current values and why.

Sheet Model_Weights
A1: Model weights (from model_weights.json)
A3: beta_hat -- fitted macro-sensitivity coefficients per tranche/cascade stage
A4: Tranche | B4: Stage | C4: Intercept (X0) | D4: Delta Earnings (X1) | E4: Delta Yield (X2) | F4: Interaction (X3)
A5: IG | B5: A | C5: -5.347574 | D5: -1.2026217 | E5: 0.7248806 | F5: -0.88132101
A6: IG | B6: B | C6: -1.4525455 | D6: -0.62906619 | E6: 0.64932307 | F6: 2.3121599
A7: IG | B7: C | C7: -0.94906764 | D7: -0.12353296 | E7: -0.85419814 | F7: -0.70593718
A8: NonIG | B8: A | C8: -4.1692218 | D8: -1.1289362 | E8: 0.91330029 | F8: -0.56723426
A9: NonIG | B9: B | C9: -1.2495275 | D9: -0.2934641 | E9: 0.44966352 | F9: -0.90981841
A10: Junk | B10: A | C10: -2.588369 | D10: -0.84275116 | E10: 1.3577344 | F10: -0.35791084
A12: Upgrade probabilities (fixed, non-macro-sensitive -- see README.md point 3)
A13: Tranche | B13: Upgrade Prob
A14: IG | B14: 0
A15: NonIG | B15: 0.04
A16: Junk | B16: 0.05
A18: Observed X_train bounds (extrapolation-warning reference)
A19: Feature | B19: Min | C19: Max
A20: Delta Earnings (X1) | B20: -0.78106768 | C20: 0.6476016
A21: Delta Yield (X2) | B21: -0.37043616 | C21: 0.30909074
A22: Interaction (X3) | B22: -0.23989505 | C22: 0.044961301
A24: EXTRAPOLATION CAP BOUNDS (per feature -- output becomes static at/beyond these values)
A25: Feature | B25: Cap Min | C25: Cap Max
A26: Delta Earnings (X1) | B26: -2.3432031 | C26: 1.9428048
A27: Delta Yield (X2) | B27: -2 | C27: 10
A28: Interaction (X3) | B28: -3.5984258 | C28: 0.67441952
A29: Note: per-feature, not one shared multiplier -- earnings and yield saturate at very different multiples of their own training range. The interaction (X3) bound applies to the recomputed X1(capped)*X2(capped) value, so a COMBINED scenario's plateau can begin before either X1 or X2 alone reaches its own bound above.

Sheet Calc
A1: X vector: row 2 = CAPPED (drives all math below), row 3 = RAW (for the range-check warning only) | B1: X0 | C1: X1 (Earn) | D1: X2 (Yield) | E1: X3 (Inter.)
B2: 1 | C2: =MIN(MAX(C3,Model_Weights!B26),Model_Weights!C26) -> 1 | D2: =MIN(MAX(D3,Model_Weights!B27),Model_Weights!C27) -> 10 | E2: =MIN(MAX(C2*D2,Model_Weights!B28),Model_Weights!C28) -> 0.67441952
A3: X vector (RAW, uncapped) | B3: 1 | C3: =Scenario!C4 -> 1 | D3: =Scenario!C5 -> 10 | E3: =C3*D3 -> 10
A4: Capped? (text, blank if not) | C4: =IF(C2<>C3,"Delta Earnings: "&TEXT(C3,"0.000")&" -> "&TEXT(C2,"0.000"),"") | D4: =IF(D2<>D3,"Delta Yield: "&TEXT(D3,"0.000")&" -> "&TEXT(D2,"0.000"),"") | E4: =IF(E2<>E3,"Interaction: "&TEXT(E3,"0.000")&" -> "&TEXT(E2,"0.000"),"") -> Interaction: 10.000 -> 0.674
A7: IG
A8: logit_A | B8: =SUMPRODUCT($B$2:$E$2, Model_Weights!C5:F5) -> 0.1042302
A9: p(fall>=1) | B9: =IF(B8>=0,1/(1+EXP(-B8)),EXP(B8)/(1+EXP(B8))) -> 0.52603398
A10: p(stay) | B10: =1-B9 -> 0.47396602
A11: logit_B | B11: =SUMPRODUCT($B$2:$E$2, Model_Weights!C6:F6) -> 5.9709848
A12: p(fall>=2 | fall>=1) | B12: =IF(B11>=0,1/(1+EXP(-B11)),EXP(B11)/(1+EXP(B11))) -> 0.99745477
A13: p(fall=1) | B13: =B9*(1-B12) -> 0.0013388788
A14: p(fall>=2) | B14: =B9*B12 -> 0.52469511
A15: logit_C | B15: =SUMPRODUCT($B$2:$E$2, Model_Weights!C7:F7) -> -10.09068
A16: p(fall=3 | fall>=2) | B16: =IF(B15>=0,1/(1+EXP(-B15)),EXP(B15)/(1+EXP(B15))) -> 4.1462493e-05
A17: p(fall=2) | B17: =B14*(1-B16) -> 0.52467335
A18: p(fall=3) | B18: =B14*B16 -> 2.1755167e-05
A19: IG row [->IG, ->NonIG, ->Junk, ->Default] | B19: =B10 -> 0.47396602 | C19: =B13 -> 0.0013388788 | D19: =B17 -> 0.52467335 | E19: =B18 -> 2.1755167e-05
A21: NonIG
A22: logit_A | B22: =SUMPRODUCT($B$2:$E$2, Model_Weights!C8:F8) -> 3.452291
A23: p(fall>=1) | B23: =IF(B22>=0,1/(1+EXP(-B22)),EXP(B22)/(1+EXP(B22))) -> 0.96929939
A24: p(stay) | B24: =1-B23 -> 0.030700609
A25: logit_B | B25: =SUMPRODUCT($B$2:$E$2, Model_Weights!C9:F9) -> 2.3400443
A26: p(fall=2 | fall>=1) | B26: =IF(B25>=0,1/(1+EXP(-B25)),EXP(B25)/(1+EXP(B25))) -> 0.91213964
A27: p(fall=1) | B27: =B23*(1-B26) -> 0.085162995
A28: p(fall=2) | B28: =B23*B26 -> 0.8841364
A29: u (upgrade prob) | B29: =Model_Weights!B15 -> 0.04
A30: NonIG row [->IG, ->NonIG, ->Junk, ->Default] | B30: =B29 -> 0.04 | C30: =(1-B29)*B24 -> 0.029472585 | D30: =(1-B29)*B27 -> 0.081756476 | E30: =(1-B29)*B28 -> 0.84877094
A32: Junk
A33: logit_A | B33: =SUMPRODUCT($B$2:$E$2, Model_Weights!C10:F10) -> 9.9048415
A34: p(fall=1) | B34: =IF(B33>=0,1/(1+EXP(-B33)),EXP(B33)/(1+EXP(B33))) -> 0.99995007
A35: p(stay) | B35: =1-B34 -> 4.9929857e-05
A36: u (upgrade prob) | B36: =Model_Weights!B16 -> 0.05
A37: Junk row [->IG, ->NonIG, ->Junk, ->Default] | B37: 0 | C37: =B36 -> 0.05 | D37: =(1-B36)*B35 -> 4.7433364e-05 | E37: =(1-B36)*B34 -> 0.94995257
A38: M (Next-Quarter Transition Matrix) [IG, NonIG, Junk, Default]
B39: =B19 -> 0.47396602 | C39: =C19 -> 0.0013388788 | D39: =D19 -> 0.52467335 | E39: =E19 -> 2.1755167e-05
B40: =B30 -> 0.04 | C40: =C30 -> 0.029472585 | D40: =D30 -> 0.081756476 | E40: =E30 -> 0.84877094
B41: =B37 -> 0 | C41: =C37 -> 0.05 | D41: =D37 -> 4.7433364e-05 | E41: =E37 -> 0.94995257
B42: 0 | C42: 0 | D42: 0 | E42: 1
A43: Cumulative transition matrix chain, quarters 1-60 (each block = MMULT(previous block, M)). Block 1 = M itself.
B44: =B39 -> 0.47396602 | C44: =C39 -> 0.0013388788 | D44: =D39 -> 0.52467335 | E44: =E39 -> 2.1755167e-05
...
